{
  "cells": [
    {
      "cell_type": "code",
      "execution_count": 2,
      "metadata": {
        "id": "tVsqIskuTPPd"
      },
      "outputs": [],
      "source": [
        "SEED = 0"
      ]
    },
    {
      "cell_type": "code",
      "execution_count": null,
      "metadata": {
        "colab": {
          "base_uri": "https://localhost:8080/"
        },
        "id": "uVG-xjy9TPA3",
        "outputId": "cf7d485b-dab9-4689-e4e1-bf2f14a15da3"
      },
      "outputs": [
        {
          "name": "stdout",
          "output_type": "stream",
          "text": [
            "Drive already mounted at /content/gdrive; to attempt to forcibly remount, call drive.mount(\"/content/gdrive\", force_remount=True).\n",
            "/content/gdrive/My Drive/Kaggle\n"
          ]
        }
      ],
      "source": [
        "from google.colab import drive\n",
        "drive.mount('/content/gdrive')\n",
        "import os\n",
        "os.environ['KAGGLE_CONFIG_DIR'] = \"/content/gdrive/My Drive/Kaggle\"\n",
        "%cd /content/gdrive/My Drive/Kaggle\n"
      ]
    },
    {
      "cell_type": "code",
      "execution_count": null,
      "metadata": {
        "id": "gogXFXCCpC6w"
      },
      "outputs": [],
      "source": [
        "!kaggle datasets download -d mlg-ulb/creditcardfraud\n"
      ]
    },
    {
      "cell_type": "code",
      "execution_count": null,
      "metadata": {
        "id": "nOtUd_lapEqw"
      },
      "outputs": [],
      "source": [
        "!unzip \\*.zip  && rm *.zip\n",
        "!ls"
      ]
    },
    {
      "cell_type": "code",
      "execution_count": 5,
      "metadata": {
        "colab": {
          "base_uri": "https://localhost:8080/",
          "height": 300
        },
        "id": "27OKsSZbTfho",
        "outputId": "9c2cb83d-8c58-4b0b-fa03-ed64c508e4a4"
      },
      "outputs": [
        {
          "ename": "FileNotFoundError",
          "evalue": "[Errno 2] No such file or directory: '/content/gdrive/My Drive/Kaggle/creditcard.csv'",
          "output_type": "error",
          "traceback": [
            "\u001b[0;31m---------------------------------------------------------------------------\u001b[0m",
            "\u001b[0;31mFileNotFoundError\u001b[0m                         Traceback (most recent call last)",
            "Cell \u001b[0;32mIn[5], line 5\u001b[0m\n\u001b[1;32m      2\u001b[0m \u001b[39mimport\u001b[39;00m \u001b[39mpandas\u001b[39;00m \u001b[39mas\u001b[39;00m \u001b[39mpd\u001b[39;00m\n\u001b[1;32m      3\u001b[0m \u001b[39mimport\u001b[39;00m \u001b[39mnumpy\u001b[39;00m \u001b[39mas\u001b[39;00m \u001b[39mnp\u001b[39;00m\n\u001b[0;32m----> 5\u001b[0m data \u001b[39m=\u001b[39m pd\u001b[39m.\u001b[39;49mread_csv(\u001b[39m\"\u001b[39;49m\u001b[39m/content/gdrive/My Drive/Kaggle/creditcard.csv\u001b[39;49m\u001b[39m\"\u001b[39;49m, header\u001b[39m=\u001b[39;49m\u001b[39m0\u001b[39;49m)\n\u001b[1;32m      6\u001b[0m data\u001b[39m.\u001b[39mhead()\n",
            "File \u001b[0;32m~/Desktop/Spring23/Projects/jupyter_test/.venv/lib/python3.10/site-packages/pandas/io/parsers/readers.py:912\u001b[0m, in \u001b[0;36mread_csv\u001b[0;34m(filepath_or_buffer, sep, delimiter, header, names, index_col, usecols, dtype, engine, converters, true_values, false_values, skipinitialspace, skiprows, skipfooter, nrows, na_values, keep_default_na, na_filter, verbose, skip_blank_lines, parse_dates, infer_datetime_format, keep_date_col, date_parser, date_format, dayfirst, cache_dates, iterator, chunksize, compression, thousands, decimal, lineterminator, quotechar, quoting, doublequote, escapechar, comment, encoding, encoding_errors, dialect, on_bad_lines, delim_whitespace, low_memory, memory_map, float_precision, storage_options, dtype_backend)\u001b[0m\n\u001b[1;32m    899\u001b[0m kwds_defaults \u001b[39m=\u001b[39m _refine_defaults_read(\n\u001b[1;32m    900\u001b[0m     dialect,\n\u001b[1;32m    901\u001b[0m     delimiter,\n\u001b[0;32m   (...)\u001b[0m\n\u001b[1;32m    908\u001b[0m     dtype_backend\u001b[39m=\u001b[39mdtype_backend,\n\u001b[1;32m    909\u001b[0m )\n\u001b[1;32m    910\u001b[0m kwds\u001b[39m.\u001b[39mupdate(kwds_defaults)\n\u001b[0;32m--> 912\u001b[0m \u001b[39mreturn\u001b[39;00m _read(filepath_or_buffer, kwds)\n",
            "File \u001b[0;32m~/Desktop/Spring23/Projects/jupyter_test/.venv/lib/python3.10/site-packages/pandas/io/parsers/readers.py:577\u001b[0m, in \u001b[0;36m_read\u001b[0;34m(filepath_or_buffer, kwds)\u001b[0m\n\u001b[1;32m    574\u001b[0m _validate_names(kwds\u001b[39m.\u001b[39mget(\u001b[39m\"\u001b[39m\u001b[39mnames\u001b[39m\u001b[39m\"\u001b[39m, \u001b[39mNone\u001b[39;00m))\n\u001b[1;32m    576\u001b[0m \u001b[39m# Create the parser.\u001b[39;00m\n\u001b[0;32m--> 577\u001b[0m parser \u001b[39m=\u001b[39m TextFileReader(filepath_or_buffer, \u001b[39m*\u001b[39;49m\u001b[39m*\u001b[39;49mkwds)\n\u001b[1;32m    579\u001b[0m \u001b[39mif\u001b[39;00m chunksize \u001b[39mor\u001b[39;00m iterator:\n\u001b[1;32m    580\u001b[0m     \u001b[39mreturn\u001b[39;00m parser\n",
            "File \u001b[0;32m~/Desktop/Spring23/Projects/jupyter_test/.venv/lib/python3.10/site-packages/pandas/io/parsers/readers.py:1407\u001b[0m, in \u001b[0;36mTextFileReader.__init__\u001b[0;34m(self, f, engine, **kwds)\u001b[0m\n\u001b[1;32m   1404\u001b[0m     \u001b[39mself\u001b[39m\u001b[39m.\u001b[39moptions[\u001b[39m\"\u001b[39m\u001b[39mhas_index_names\u001b[39m\u001b[39m\"\u001b[39m] \u001b[39m=\u001b[39m kwds[\u001b[39m\"\u001b[39m\u001b[39mhas_index_names\u001b[39m\u001b[39m\"\u001b[39m]\n\u001b[1;32m   1406\u001b[0m \u001b[39mself\u001b[39m\u001b[39m.\u001b[39mhandles: IOHandles \u001b[39m|\u001b[39m \u001b[39mNone\u001b[39;00m \u001b[39m=\u001b[39m \u001b[39mNone\u001b[39;00m\n\u001b[0;32m-> 1407\u001b[0m \u001b[39mself\u001b[39m\u001b[39m.\u001b[39m_engine \u001b[39m=\u001b[39m \u001b[39mself\u001b[39;49m\u001b[39m.\u001b[39;49m_make_engine(f, \u001b[39mself\u001b[39;49m\u001b[39m.\u001b[39;49mengine)\n",
            "File \u001b[0;32m~/Desktop/Spring23/Projects/jupyter_test/.venv/lib/python3.10/site-packages/pandas/io/parsers/readers.py:1661\u001b[0m, in \u001b[0;36mTextFileReader._make_engine\u001b[0;34m(self, f, engine)\u001b[0m\n\u001b[1;32m   1659\u001b[0m     \u001b[39mif\u001b[39;00m \u001b[39m\"\u001b[39m\u001b[39mb\u001b[39m\u001b[39m\"\u001b[39m \u001b[39mnot\u001b[39;00m \u001b[39min\u001b[39;00m mode:\n\u001b[1;32m   1660\u001b[0m         mode \u001b[39m+\u001b[39m\u001b[39m=\u001b[39m \u001b[39m\"\u001b[39m\u001b[39mb\u001b[39m\u001b[39m\"\u001b[39m\n\u001b[0;32m-> 1661\u001b[0m \u001b[39mself\u001b[39m\u001b[39m.\u001b[39mhandles \u001b[39m=\u001b[39m get_handle(\n\u001b[1;32m   1662\u001b[0m     f,\n\u001b[1;32m   1663\u001b[0m     mode,\n\u001b[1;32m   1664\u001b[0m     encoding\u001b[39m=\u001b[39;49m\u001b[39mself\u001b[39;49m\u001b[39m.\u001b[39;49moptions\u001b[39m.\u001b[39;49mget(\u001b[39m\"\u001b[39;49m\u001b[39mencoding\u001b[39;49m\u001b[39m\"\u001b[39;49m, \u001b[39mNone\u001b[39;49;00m),\n\u001b[1;32m   1665\u001b[0m     compression\u001b[39m=\u001b[39;49m\u001b[39mself\u001b[39;49m\u001b[39m.\u001b[39;49moptions\u001b[39m.\u001b[39;49mget(\u001b[39m\"\u001b[39;49m\u001b[39mcompression\u001b[39;49m\u001b[39m\"\u001b[39;49m, \u001b[39mNone\u001b[39;49;00m),\n\u001b[1;32m   1666\u001b[0m     memory_map\u001b[39m=\u001b[39;49m\u001b[39mself\u001b[39;49m\u001b[39m.\u001b[39;49moptions\u001b[39m.\u001b[39;49mget(\u001b[39m\"\u001b[39;49m\u001b[39mmemory_map\u001b[39;49m\u001b[39m\"\u001b[39;49m, \u001b[39mFalse\u001b[39;49;00m),\n\u001b[1;32m   1667\u001b[0m     is_text\u001b[39m=\u001b[39;49mis_text,\n\u001b[1;32m   1668\u001b[0m     errors\u001b[39m=\u001b[39;49m\u001b[39mself\u001b[39;49m\u001b[39m.\u001b[39;49moptions\u001b[39m.\u001b[39;49mget(\u001b[39m\"\u001b[39;49m\u001b[39mencoding_errors\u001b[39;49m\u001b[39m\"\u001b[39;49m, \u001b[39m\"\u001b[39;49m\u001b[39mstrict\u001b[39;49m\u001b[39m\"\u001b[39;49m),\n\u001b[1;32m   1669\u001b[0m     storage_options\u001b[39m=\u001b[39;49m\u001b[39mself\u001b[39;49m\u001b[39m.\u001b[39;49moptions\u001b[39m.\u001b[39;49mget(\u001b[39m\"\u001b[39;49m\u001b[39mstorage_options\u001b[39;49m\u001b[39m\"\u001b[39;49m, \u001b[39mNone\u001b[39;49;00m),\n\u001b[1;32m   1670\u001b[0m )\n\u001b[1;32m   1671\u001b[0m \u001b[39massert\u001b[39;00m \u001b[39mself\u001b[39m\u001b[39m.\u001b[39mhandles \u001b[39mis\u001b[39;00m \u001b[39mnot\u001b[39;00m \u001b[39mNone\u001b[39;00m\n\u001b[1;32m   1672\u001b[0m f \u001b[39m=\u001b[39m \u001b[39mself\u001b[39m\u001b[39m.\u001b[39mhandles\u001b[39m.\u001b[39mhandle\n",
            "File \u001b[0;32m~/Desktop/Spring23/Projects/jupyter_test/.venv/lib/python3.10/site-packages/pandas/io/common.py:859\u001b[0m, in \u001b[0;36mget_handle\u001b[0;34m(path_or_buf, mode, encoding, compression, memory_map, is_text, errors, storage_options)\u001b[0m\n\u001b[1;32m    854\u001b[0m \u001b[39melif\u001b[39;00m \u001b[39misinstance\u001b[39m(handle, \u001b[39mstr\u001b[39m):\n\u001b[1;32m    855\u001b[0m     \u001b[39m# Check whether the filename is to be opened in binary mode.\u001b[39;00m\n\u001b[1;32m    856\u001b[0m     \u001b[39m# Binary mode does not support 'encoding' and 'newline'.\u001b[39;00m\n\u001b[1;32m    857\u001b[0m     \u001b[39mif\u001b[39;00m ioargs\u001b[39m.\u001b[39mencoding \u001b[39mand\u001b[39;00m \u001b[39m\"\u001b[39m\u001b[39mb\u001b[39m\u001b[39m\"\u001b[39m \u001b[39mnot\u001b[39;00m \u001b[39min\u001b[39;00m ioargs\u001b[39m.\u001b[39mmode:\n\u001b[1;32m    858\u001b[0m         \u001b[39m# Encoding\u001b[39;00m\n\u001b[0;32m--> 859\u001b[0m         handle \u001b[39m=\u001b[39m \u001b[39mopen\u001b[39;49m(\n\u001b[1;32m    860\u001b[0m             handle,\n\u001b[1;32m    861\u001b[0m             ioargs\u001b[39m.\u001b[39;49mmode,\n\u001b[1;32m    862\u001b[0m             encoding\u001b[39m=\u001b[39;49mioargs\u001b[39m.\u001b[39;49mencoding,\n\u001b[1;32m    863\u001b[0m             errors\u001b[39m=\u001b[39;49merrors,\n\u001b[1;32m    864\u001b[0m             newline\u001b[39m=\u001b[39;49m\u001b[39m\"\u001b[39;49m\u001b[39m\"\u001b[39;49m,\n\u001b[1;32m    865\u001b[0m         )\n\u001b[1;32m    866\u001b[0m     \u001b[39melse\u001b[39;00m:\n\u001b[1;32m    867\u001b[0m         \u001b[39m# Binary mode\u001b[39;00m\n\u001b[1;32m    868\u001b[0m         handle \u001b[39m=\u001b[39m \u001b[39mopen\u001b[39m(handle, ioargs\u001b[39m.\u001b[39mmode)\n",
            "\u001b[0;31mFileNotFoundError\u001b[0m: [Errno 2] No such file or directory: '/content/gdrive/My Drive/Kaggle/creditcard.csv'"
          ]
        }
      ],
      "source": [
        "#Loading data\n",
        "import pandas as pd\n",
        "import numpy as np\n",
        "\n",
        "data = pd.read_csv(\"/content/gdrive/My Drive/Kaggle/creditcard.csv\", header=0)\n",
        "data.head()"
      ]
    },
    {
      "cell_type": "code",
      "execution_count": 4,
      "metadata": {
        "colab": {
          "base_uri": "https://localhost:8080/"
        },
        "id": "ZWt-gnh8UMv4",
        "outputId": "f1ab1989-3ac2-4f3a-9ced-f59495f468fd"
      },
      "outputs": [
        {
          "ename": "NameError",
          "evalue": "name 'data' is not defined",
          "output_type": "error",
          "traceback": [
            "\u001b[0;31m---------------------------------------------------------------------------\u001b[0m",
            "\u001b[0;31mNameError\u001b[0m                                 Traceback (most recent call last)",
            "Cell \u001b[0;32mIn[4], line 2\u001b[0m\n\u001b[1;32m      1\u001b[0m \u001b[39m#Handle Duplicated values\u001b[39;00m\n\u001b[0;32m----> 2\u001b[0m \u001b[39mprint\u001b[39m(\u001b[39m\"\u001b[39m\u001b[39mDuplicates\u001b[39m\u001b[39m\"\u001b[39m, data\u001b[39m.\u001b[39mduplicated()\u001b[39m.\u001b[39msum())\n\u001b[1;32m      3\u001b[0m data \u001b[39m=\u001b[39m data\u001b[39m.\u001b[39mdrop_duplicates()\n\u001b[1;32m      4\u001b[0m \u001b[39mprint\u001b[39m(\u001b[39m\"\u001b[39m\u001b[39mRows \u001b[39m\u001b[39m{}\u001b[39;00m\u001b[39m, Columns \u001b[39m\u001b[39m{}\u001b[39;00m\u001b[39m\"\u001b[39m\u001b[39m.\u001b[39mformat(data\u001b[39m.\u001b[39mshape[\u001b[39m0\u001b[39m], data\u001b[39m.\u001b[39mshape[\u001b[39m1\u001b[39m]))\n",
            "\u001b[0;31mNameError\u001b[0m: name 'data' is not defined"
          ]
        }
      ],
      "source": [
        "#Handle Duplicated values\n",
        "print(\"Duplicates\", data.duplicated().sum())\n",
        "data = data.drop_duplicates()\n",
        "print(\"Rows {}, Columns {}\".format(data.shape[0], data.shape[1]))"
      ]
    },
    {
      "cell_type": "code",
      "execution_count": null,
      "metadata": {
        "colab": {
          "base_uri": "https://localhost:8080/"
        },
        "id": "htK4Xt1_sQWY",
        "outputId": "d381de6d-c5aa-42de-a38c-666fdc3d9b64"
      },
      "outputs": [
        {
          "data": {
            "text/plain": [
              "0    283253\n",
              "1       473\n",
              "Name: Class, dtype: int64"
            ]
          },
          "execution_count": 38,
          "metadata": {},
          "output_type": "execute_result"
        }
      ],
      "source": [
        "data['Class'] = data['Class'].replace({'0': 0, '1': 1})\n",
        "data['Class'].unique()\n",
        "data['Class'].value_counts()"
      ]
    },
    {
      "cell_type": "code",
      "execution_count": null,
      "metadata": {
        "colab": {
          "base_uri": "https://localhost:8080/"
        },
        "id": "0K2Gol_bUPPQ",
        "outputId": "d9e1a992-4cdb-4550-9f19-76eb33cc96a8"
      },
      "outputs": [
        {
          "data": {
            "text/plain": [
              "0    283253\n",
              "1       473\n",
              "Name: Class, dtype: int64"
            ]
          },
          "execution_count": 39,
          "metadata": {},
          "output_type": "execute_result"
        }
      ],
      "source": [
        "labels = data['Class'] \n",
        "data = data[data.columns[:-1]]\n",
        "labels.value_counts()"
      ]
    },
    {
      "cell_type": "code",
      "execution_count": null,
      "metadata": {
        "id": "vXkrEsCnURpd"
      },
      "outputs": [],
      "source": [
        "from sklearn.model_selection import train_test_split\n",
        "\n",
        "X_train, X_test, y_train, y_test = train_test_split( data, labels, test_size=0.3, random_state=SEED, stratify = labels )"
      ]
    },
    {
      "cell_type": "code",
      "execution_count": null,
      "metadata": {
        "id": "Yd_B3iT3i9_C"
      },
      "outputs": [],
      "source": []
    },
    {
      "cell_type": "code",
      "execution_count": null,
      "metadata": {
        "colab": {
          "background_save": true,
          "base_uri": "https://localhost:8080/"
        },
        "id": "CqkgvW9sTLBL",
        "outputId": "1c7a73ed-089d-4132-c5df-634bdfd31dbe"
      },
      "outputs": [
        {
          "name": "stderr",
          "output_type": "stream",
          "text": [
            "/usr/local/lib/python3.9/dist-packages/sklearn/ensemble/_base.py:166: FutureWarning: `base_estimator` was renamed to `estimator` in version 1.2 and will be removed in 1.4.\n",
            "  warnings.warn(\n"
          ]
        },
        {
          "name": "stdout",
          "output_type": "stream",
          "text": [
            "              precision    recall  f1-score   support\n",
            "\n",
            "           0       1.00      1.00      1.00     84976\n",
            "           1       0.98      0.80      0.88       142\n",
            "\n",
            "    accuracy                           1.00     85118\n",
            "   macro avg       0.99      0.90      0.94     85118\n",
            "weighted avg       1.00      1.00      1.00     85118\n",
            "\n"
          ]
        }
      ],
      "source": [
        "#Bagging using Random forest\n",
        "\n",
        "from sklearn.ensemble import RandomForestClassifier, BaggingClassifier\n",
        "from sklearn.metrics import classification_report, confusion_matrix\n",
        "from imblearn.ensemble import BalancedBaggingClassifier\n",
        "\n",
        "# Define the base classifier\n",
        "base_clf = RandomForestClassifier()\n",
        "\n",
        "# Define the bagging classifier\n",
        "bagging_clf = BaggingClassifier(base_estimator=base_clf, n_estimators=10)\n",
        "\n",
        "# Train the bagging classifier on the training data\n",
        "bagging_clf.fit(X_train, y_train)\n",
        "\n",
        "# Evaluate the bagging classifier on the test data\n",
        "y_pred = bagging_clf.predict(X_test)\n",
        "print(classification_report(y_test, y_pred))\n"
      ]
    },
    {
      "cell_type": "code",
      "execution_count": null,
      "metadata": {
        "colab": {
          "background_save": true
        },
        "id": "mHku7KWsU3sk",
        "outputId": "3beeed0c-8d10-490e-df84-f8f281361f43"
      },
      "outputs": [
        {
          "name": "stderr",
          "output_type": "stream",
          "text": [
            "/usr/local/lib/python3.9/dist-packages/sklearn/ensemble/_base.py:166: FutureWarning: `base_estimator` was renamed to `estimator` in version 1.2 and will be removed in 1.4.\n",
            "  warnings.warn(\n"
          ]
        },
        {
          "name": "stdout",
          "output_type": "stream",
          "text": [
            "              precision    recall  f1-score   support\n",
            "\n",
            "           0       1.00      1.00      1.00     84976\n",
            "           1       0.72      0.77      0.74       142\n",
            "\n",
            "    accuracy                           1.00     85118\n",
            "   macro avg       0.86      0.88      0.87     85118\n",
            "weighted avg       1.00      1.00      1.00     85118\n",
            "\n",
            "Confusion Matrix:\n",
            " [[84934    42]\n",
            " [   33   109]]\n"
          ]
        }
      ],
      "source": [
        "#Boosting using Decision Tree\n",
        "from sklearn.ensemble import AdaBoostClassifier, DecisionTreeClassifier\n",
        "\n",
        "from sklearn.metrics import classification_report\n",
        "\n",
        "# Define the base classifier\n",
        "base_clf = DecisionTreeClassifier()\n",
        "\n",
        "# Define the boosting classifier\n",
        "boosting_clf = AdaBoostClassifier(base_estimator=base_clf, n_estimators=50, learning_rate=1)\n",
        "\n",
        "# Train the boosting classifier on the training data\n",
        "boosting_clf.fit(X_train, y_train)\n",
        "\n",
        "# Evaluate the boosting classifier on the test data\n",
        "y_pred = boosting_clf.predict(X_test)\n",
        "print(classification_report(y_test, y_pred))\n"
      ]
    },
    {
      "cell_type": "code",
      "execution_count": 1,
      "metadata": {
        "id": "ON-zjxZfqdGm"
      },
      "outputs": [
        {
          "ename": "NameError",
          "evalue": "name 'SEED' is not defined",
          "output_type": "error",
          "traceback": [
            "\u001b[0;31m---------------------------------------------------------------------------\u001b[0m",
            "\u001b[0;31mNameError\u001b[0m                                 Traceback (most recent call last)",
            "Cell \u001b[0;32mIn[1], line 7\u001b[0m\n\u001b[1;32m      4\u001b[0m \u001b[39mfrom\u001b[39;00m \u001b[39msklearn\u001b[39;00m\u001b[39m.\u001b[39;00m\u001b[39mmodel_selection\u001b[39;00m \u001b[39mimport\u001b[39;00m train_test_split\n\u001b[1;32m      6\u001b[0m \u001b[39m# Define AdaBoost classifier and specify the minority class weight\u001b[39;00m\n\u001b[0;32m----> 7\u001b[0m ada \u001b[39m=\u001b[39m AdaBoostClassifier(n_estimators\u001b[39m=\u001b[39m\u001b[39m50\u001b[39m, random_state\u001b[39m=\u001b[39mSEED, algorithm\u001b[39m=\u001b[39m\u001b[39m'\u001b[39m\u001b[39mSAMME.R\u001b[39m\u001b[39m'\u001b[39m, \n\u001b[1;32m      8\u001b[0m                          learning_rate\u001b[39m=\u001b[39m\u001b[39m1.0\u001b[39m, class_weight\u001b[39m=\u001b[39m\u001b[39m'\u001b[39m\u001b[39mbalanced\u001b[39m\u001b[39m'\u001b[39m)\n\u001b[1;32m     10\u001b[0m \u001b[39m# Train the classifier\u001b[39;00m\n\u001b[1;32m     11\u001b[0m ada\u001b[39m.\u001b[39mfit(X_train, y_train)\n",
            "\u001b[0;31mNameError\u001b[0m: name 'SEED' is not defined"
          ]
        }
      ],
      "source": [
        "#Ada boost with weight balanced\n",
        "from sklearn.ensemble import AdaBoostClassifier\n",
        "from sklearn.datasets import make_classification\n",
        "from sklearn.model_selection import train_test_split\n",
        "\n",
        "# Define AdaBoost classifier and specify the minority class weight\n",
        "ada = AdaBoostClassifier(n_estimators=50, random_state=SEED, algorithm='SAMME.R', \n",
        "                         learning_rate=1.0, class_weight='balanced')\n",
        "\n",
        "# Train the classifier\n",
        "ada.fit(X_train, y_train)\n",
        "\n",
        "# Predict on test data\n",
        "y_pred = ada.predict(X_test)\n",
        "\n",
        "# Evaluate performance\n",
        "from sklearn.metrics import confusion_matrix, classification_report\n",
        "print(\"Confusion Matrix:\\n\", confusion_matrix(y_test, y_pred))\n",
        "print(\"\\nClassification Report:\\n\", classification_report(y_test, y_pred))\n"
      ]
    },
    {
      "cell_type": "code",
      "execution_count": null,
      "metadata": {
        "colab": {
          "base_uri": "https://localhost:8080/"
        },
        "id": "vNGJgT56WBFH",
        "outputId": "c121e3ae-e623-46a9-c784-5bf57db66fe6"
      },
      "outputs": [
        {
          "name": "stdout",
          "output_type": "stream",
          "text": [
            "Confusion Matrix:\n",
            " [[84970     6]\n",
            " [   23   119]]\n",
            "\n",
            "Classification Report:\n",
            "               precision    recall  f1-score   support\n",
            "\n",
            "           0       1.00      1.00      1.00     84976\n",
            "           1       0.95      0.84      0.89       142\n",
            "\n",
            "    accuracy                           1.00     85118\n",
            "   macro avg       0.98      0.92      0.95     85118\n",
            "weighted avg       1.00      1.00      1.00     85118\n",
            "\n"
          ]
        }
      ],
      "source": [
        "from xgboost import XGBClassifier\n",
        "from sklearn.metrics import confusion_matrix, classification_report, ConfusionMatrixDisplay\n",
        "from imblearn.over_sampling import RandomOverSampler\n",
        "\n",
        "ratio = float(np.sum(y_train == 0)) / np.sum(y_train == 1)  # Compute class ratio\n",
        "xgb_clf = XGBClassifier(scale_pos_weight=ratio, random_state=SEED)\n",
        "\n",
        "# Train the classifier\n",
        "xgb_clf.fit(X_train, y_train)\n",
        "\n",
        "# Predict on test data\n",
        "y_pred = xgb_clf.predict(X_test)\n",
        "\n",
        "# Evaluate performance\n",
        "print(\"Confusion Matrix:\\n\", confusion_matrix(y_test, y_pred))\n",
        "print(\"\\nClassification Report:\\n\", classification_report(y_test, y_pred))\n"
      ]
    },
    {
      "cell_type": "code",
      "execution_count": null,
      "metadata": {
        "colab": {
          "background_save": true,
          "base_uri": "https://localhost:8080/",
          "height": 187
        },
        "id": "w9T9Fa4Beabk",
        "outputId": "e1aa5169-6b83-4e19-9eba-1f8fa1ffe5ef"
      },
      "outputs": [
        {
          "name": "stderr",
          "output_type": "stream",
          "text": [
            "ERROR:root:Internal Python error in the inspect module.\n",
            "Below is the traceback from this internal error.\n",
            "\n",
            "ERROR:root:Internal Python error in the inspect module.\n",
            "Below is the traceback from this internal error.\n",
            "\n",
            "ERROR:root:Internal Python error in the inspect module.\n",
            "Below is the traceback from this internal error.\n",
            "\n"
          ]
        },
        {
          "name": "stdout",
          "output_type": "stream",
          "text": [
            "Traceback (most recent call last):\n",
            "  File \"/usr/local/lib/python3.9/dist-packages/IPython/core/interactiveshell.py\", line 3553, in run_code\n",
            "    exec(code_obj, self.user_global_ns, self.user_ns)\n",
            "  File \"<ipython-input-41-3552819214f8>\", line 2, in <cell line: 2>\n",
            "    print(\"\\n\", ConfusionMatrixDisplay.from_estimator(xgb_clf, X_test_pca, y_test, display_labels=labels.unique()))\n",
            "NameError: name 'X_test_pca' is not defined\n",
            "\n",
            "During handling of the above exception, another exception occurred:\n",
            "\n",
            "Traceback (most recent call last):\n",
            "  File \"/usr/local/lib/python3.9/dist-packages/IPython/core/interactiveshell.py\", line 2099, in showtraceback\n",
            "    stb = value._render_traceback_()\n",
            "AttributeError: 'NameError' object has no attribute '_render_traceback_'\n",
            "\n",
            "During handling of the above exception, another exception occurred:\n",
            "\n",
            "Traceback (most recent call last):\n",
            "  File \"/usr/local/lib/python3.9/dist-packages/IPython/core/ultratb.py\", line 1101, in get_records\n",
            "    return _fixed_getinnerframes(etb, number_of_lines_of_context, tb_offset)\n",
            "  File \"/usr/local/lib/python3.9/dist-packages/IPython/core/ultratb.py\", line 248, in wrapped\n",
            "    return f(*args, **kwargs)\n",
            "  File \"/usr/local/lib/python3.9/dist-packages/IPython/core/ultratb.py\", line 281, in _fixed_getinnerframes\n",
            "    records = fix_frame_records_filenames(inspect.getinnerframes(etb, context))\n",
            "  File \"/usr/lib/python3.9/inspect.py\", line 1543, in getinnerframes\n",
            "    frameinfo = (tb.tb_frame,) + getframeinfo(tb, context)\n",
            "  File \"/usr/lib/python3.9/inspect.py\", line 1501, in getframeinfo\n",
            "    filename = getsourcefile(frame) or getfile(frame)\n",
            "  File \"/usr/lib/python3.9/inspect.py\", line 709, in getsourcefile\n",
            "    if getattr(getmodule(object, filename), '__loader__', None) is not None:\n",
            "  File \"/usr/lib/python3.9/inspect.py\", line 738, in getmodule\n",
            "    file = getabsfile(object, _filename)\n",
            "  File \"/usr/lib/python3.9/inspect.py\", line 722, in getabsfile\n",
            "    return os.path.normcase(os.path.abspath(_filename))\n",
            "  File \"/usr/lib/python3.9/posixpath.py\", line 380, in abspath\n",
            "    cwd = os.getcwd()\n",
            "OSError: [Errno 107] Transport endpoint is not connected\n",
            "Traceback (most recent call last):\n",
            "  File \"/usr/local/lib/python3.9/dist-packages/IPython/core/interactiveshell.py\", line 3553, in run_code\n",
            "    exec(code_obj, self.user_global_ns, self.user_ns)\n",
            "  File \"<ipython-input-41-3552819214f8>\", line 2, in <cell line: 2>\n",
            "    print(\"\\n\", ConfusionMatrixDisplay.from_estimator(xgb_clf, X_test_pca, y_test, display_labels=labels.unique()))\n",
            "NameError: name 'X_test_pca' is not defined\n",
            "\n",
            "During handling of the above exception, another exception occurred:\n",
            "\n",
            "Traceback (most recent call last):\n",
            "  File \"/usr/local/lib/python3.9/dist-packages/IPython/core/interactiveshell.py\", line 2099, in showtraceback\n",
            "    stb = value._render_traceback_()\n",
            "AttributeError: 'NameError' object has no attribute '_render_traceback_'\n",
            "\n",
            "During handling of the above exception, another exception occurred:\n",
            "\n",
            "Traceback (most recent call last):\n",
            "  File \"/usr/local/lib/python3.9/dist-packages/IPython/core/interactiveshell.py\", line 3473, in run_ast_nodes\n",
            "    if (await self.run_code(code, result,  async_=asy)):\n",
            "  File \"/usr/local/lib/python3.9/dist-packages/IPython/core/interactiveshell.py\", line 3575, in run_code\n",
            "    self.showtraceback(running_compiled_code=True)\n",
            "  File \"/usr/local/lib/python3.9/dist-packages/IPython/core/interactiveshell.py\", line 2101, in showtraceback\n",
            "    stb = self.InteractiveTB.structured_traceback(etype,\n",
            "  File \"/usr/local/lib/python3.9/dist-packages/IPython/core/ultratb.py\", line 1367, in structured_traceback\n",
            "    return FormattedTB.structured_traceback(\n",
            "  File \"/usr/local/lib/python3.9/dist-packages/IPython/core/ultratb.py\", line 1267, in structured_traceback\n",
            "    return VerboseTB.structured_traceback(\n",
            "  File \"/usr/local/lib/python3.9/dist-packages/IPython/core/ultratb.py\", line 1124, in structured_traceback\n",
            "    formatted_exception = self.format_exception_as_a_whole(etype, evalue, etb, number_of_lines_of_context,\n",
            "  File \"/usr/local/lib/python3.9/dist-packages/IPython/core/ultratb.py\", line 1082, in format_exception_as_a_whole\n",
            "    last_unique, recursion_repeat = find_recursion(orig_etype, evalue, records)\n",
            "  File \"/usr/local/lib/python3.9/dist-packages/IPython/core/ultratb.py\", line 382, in find_recursion\n",
            "    return len(records), 0\n",
            "TypeError: object of type 'NoneType' has no len()\n",
            "\n",
            "During handling of the above exception, another exception occurred:\n",
            "\n",
            "Traceback (most recent call last):\n",
            "  File \"/usr/local/lib/python3.9/dist-packages/IPython/core/interactiveshell.py\", line 2099, in showtraceback\n",
            "    stb = value._render_traceback_()\n",
            "AttributeError: 'TypeError' object has no attribute '_render_traceback_'\n",
            "\n",
            "During handling of the above exception, another exception occurred:\n",
            "\n",
            "Traceback (most recent call last):\n",
            "  File \"/usr/local/lib/python3.9/dist-packages/IPython/core/ultratb.py\", line 1101, in get_records\n",
            "    return _fixed_getinnerframes(etb, number_of_lines_of_context, tb_offset)\n",
            "  File \"/usr/local/lib/python3.9/dist-packages/IPython/core/ultratb.py\", line 248, in wrapped\n",
            "    return f(*args, **kwargs)\n",
            "  File \"/usr/local/lib/python3.9/dist-packages/IPython/core/ultratb.py\", line 281, in _fixed_getinnerframes\n",
            "    records = fix_frame_records_filenames(inspect.getinnerframes(etb, context))\n",
            "  File \"/usr/lib/python3.9/inspect.py\", line 1543, in getinnerframes\n",
            "    frameinfo = (tb.tb_frame,) + getframeinfo(tb, context)\n",
            "  File \"/usr/lib/python3.9/inspect.py\", line 1501, in getframeinfo\n",
            "    filename = getsourcefile(frame) or getfile(frame)\n",
            "  File \"/usr/lib/python3.9/inspect.py\", line 709, in getsourcefile\n",
            "    if getattr(getmodule(object, filename), '__loader__', None) is not None:\n",
            "  File \"/usr/lib/python3.9/inspect.py\", line 738, in getmodule\n",
            "    file = getabsfile(object, _filename)\n",
            "  File \"/usr/lib/python3.9/inspect.py\", line 722, in getabsfile\n",
            "    return os.path.normcase(os.path.abspath(_filename))\n",
            "  File \"/usr/lib/python3.9/posixpath.py\", line 380, in abspath\n",
            "    cwd = os.getcwd()\n",
            "OSError: [Errno 107] Transport endpoint is not connected\n",
            "Traceback (most recent call last):\n",
            "  File \"/usr/local/lib/python3.9/dist-packages/IPython/core/interactiveshell.py\", line 3553, in run_code\n",
            "    exec(code_obj, self.user_global_ns, self.user_ns)\n",
            "  File \"<ipython-input-41-3552819214f8>\", line 2, in <cell line: 2>\n",
            "    print(\"\\n\", ConfusionMatrixDisplay.from_estimator(xgb_clf, X_test_pca, y_test, display_labels=labels.unique()))\n",
            "NameError: name 'X_test_pca' is not defined\n",
            "\n",
            "During handling of the above exception, another exception occurred:\n",
            "\n",
            "Traceback (most recent call last):\n",
            "  File \"/usr/local/lib/python3.9/dist-packages/IPython/core/interactiveshell.py\", line 2099, in showtraceback\n",
            "    stb = value._render_traceback_()\n",
            "AttributeError: 'NameError' object has no attribute '_render_traceback_'\n",
            "\n",
            "During handling of the above exception, another exception occurred:\n",
            "\n",
            "Traceback (most recent call last):\n",
            "  File \"/usr/local/lib/python3.9/dist-packages/IPython/core/interactiveshell.py\", line 3473, in run_ast_nodes\n",
            "    if (await self.run_code(code, result,  async_=asy)):\n",
            "  File \"/usr/local/lib/python3.9/dist-packages/IPython/core/interactiveshell.py\", line 3575, in run_code\n",
            "    self.showtraceback(running_compiled_code=True)\n",
            "  File \"/usr/local/lib/python3.9/dist-packages/IPython/core/interactiveshell.py\", line 2101, in showtraceback\n",
            "    stb = self.InteractiveTB.structured_traceback(etype,\n",
            "  File \"/usr/local/lib/python3.9/dist-packages/IPython/core/ultratb.py\", line 1367, in structured_traceback\n",
            "    return FormattedTB.structured_traceback(\n",
            "  File \"/usr/local/lib/python3.9/dist-packages/IPython/core/ultratb.py\", line 1267, in structured_traceback\n",
            "    return VerboseTB.structured_traceback(\n",
            "  File \"/usr/local/lib/python3.9/dist-packages/IPython/core/ultratb.py\", line 1124, in structured_traceback\n",
            "    formatted_exception = self.format_exception_as_a_whole(etype, evalue, etb, number_of_lines_of_context,\n",
            "  File \"/usr/local/lib/python3.9/dist-packages/IPython/core/ultratb.py\", line 1082, in format_exception_as_a_whole\n",
            "    last_unique, recursion_repeat = find_recursion(orig_etype, evalue, records)\n",
            "  File \"/usr/local/lib/python3.9/dist-packages/IPython/core/ultratb.py\", line 382, in find_recursion\n",
            "    return len(records), 0\n",
            "TypeError: object of type 'NoneType' has no len()\n",
            "\n",
            "During handling of the above exception, another exception occurred:\n",
            "\n",
            "Traceback (most recent call last):\n",
            "  File \"/usr/local/lib/python3.9/dist-packages/IPython/core/interactiveshell.py\", line 2099, in showtraceback\n",
            "    stb = value._render_traceback_()\n",
            "AttributeError: 'TypeError' object has no attribute '_render_traceback_'\n",
            "\n",
            "During handling of the above exception, another exception occurred:\n",
            "\n",
            "Traceback (most recent call last):\n",
            "  File \"/usr/local/lib/python3.9/dist-packages/IPython/core/interactiveshell.py\", line 3030, in _run_cell\n",
            "    return runner(coro)\n",
            "  File \"/usr/local/lib/python3.9/dist-packages/IPython/core/async_helpers.py\", line 78, in _pseudo_sync_runner\n",
            "    coro.send(None)\n",
            "  File \"/usr/local/lib/python3.9/dist-packages/IPython/core/interactiveshell.py\", line 3257, in run_cell_async\n",
            "    has_raised = await self.run_ast_nodes(code_ast.body, cell_name,\n",
            "  File \"/usr/local/lib/python3.9/dist-packages/IPython/core/interactiveshell.py\", line 3492, in run_ast_nodes\n",
            "    self.showtraceback()\n",
            "  File \"/usr/local/lib/python3.9/dist-packages/IPython/core/interactiveshell.py\", line 2101, in showtraceback\n",
            "    stb = self.InteractiveTB.structured_traceback(etype,\n",
            "  File \"/usr/local/lib/python3.9/dist-packages/IPython/core/ultratb.py\", line 1367, in structured_traceback\n",
            "    return FormattedTB.structured_traceback(\n",
            "  File \"/usr/local/lib/python3.9/dist-packages/IPython/core/ultratb.py\", line 1267, in structured_traceback\n",
            "    return VerboseTB.structured_traceback(\n",
            "  File \"/usr/local/lib/python3.9/dist-packages/IPython/core/ultratb.py\", line 1142, in structured_traceback\n",
            "    formatted_exceptions += self.format_exception_as_a_whole(etype, evalue, etb, lines_of_context,\n",
            "  File \"/usr/local/lib/python3.9/dist-packages/IPython/core/ultratb.py\", line 1082, in format_exception_as_a_whole\n",
            "    last_unique, recursion_repeat = find_recursion(orig_etype, evalue, records)\n",
            "  File \"/usr/local/lib/python3.9/dist-packages/IPython/core/ultratb.py\", line 382, in find_recursion\n",
            "    return len(records), 0\n",
            "TypeError: object of type 'NoneType' has no len()\n",
            "\n",
            "During handling of the above exception, another exception occurred:\n",
            "\n",
            "Traceback (most recent call last):\n",
            "  File \"/usr/local/lib/python3.9/dist-packages/IPython/core/interactiveshell.py\", line 2099, in showtraceback\n",
            "    stb = value._render_traceback_()\n",
            "AttributeError: 'TypeError' object has no attribute '_render_traceback_'\n",
            "\n",
            "During handling of the above exception, another exception occurred:\n",
            "\n",
            "Traceback (most recent call last):\n",
            "  File \"/usr/local/lib/python3.9/dist-packages/IPython/core/ultratb.py\", line 1101, in get_records\n",
            "    return _fixed_getinnerframes(etb, number_of_lines_of_context, tb_offset)\n",
            "  File \"/usr/local/lib/python3.9/dist-packages/IPython/core/ultratb.py\", line 248, in wrapped\n",
            "    return f(*args, **kwargs)\n",
            "  File \"/usr/local/lib/python3.9/dist-packages/IPython/core/ultratb.py\", line 281, in _fixed_getinnerframes\n",
            "    records = fix_frame_records_filenames(inspect.getinnerframes(etb, context))\n",
            "  File \"/usr/lib/python3.9/inspect.py\", line 1543, in getinnerframes\n",
            "    frameinfo = (tb.tb_frame,) + getframeinfo(tb, context)\n",
            "  File \"/usr/lib/python3.9/inspect.py\", line 1501, in getframeinfo\n",
            "    filename = getsourcefile(frame) or getfile(frame)\n",
            "  File \"/usr/lib/python3.9/inspect.py\", line 709, in getsourcefile\n",
            "    if getattr(getmodule(object, filename), '__loader__', None) is not None:\n",
            "  File \"/usr/lib/python3.9/inspect.py\", line 738, in getmodule\n",
            "    file = getabsfile(object, _filename)\n",
            "  File \"/usr/lib/python3.9/inspect.py\", line 722, in getabsfile\n",
            "    return os.path.normcase(os.path.abspath(_filename))\n",
            "  File \"/usr/lib/python3.9/posixpath.py\", line 380, in abspath\n",
            "    cwd = os.getcwd()\n",
            "OSError: [Errno 107] Transport endpoint is not connected\n"
          ]
        }
      ],
      "source": [
        "from sklearn.metrics import confusion_matrix, classification_report, ConfusionMatrixDisplay\n",
        "print(\"\\n\", ConfusionMatrixDisplay.from_estimator(xgb_clf, X_test_pca, y_test, display_labels=labels.unique()))"
      ]
    }
  ],
  "metadata": {
    "colab": {
      "provenance": []
    },
    "kernelspec": {
      "display_name": ".venv",
      "language": "python",
      "name": ".venv"
    },
    "language_info": {
      "codemirror_mode": {
        "name": "ipython",
        "version": 3
      },
      "file_extension": ".py",
      "mimetype": "text/x-python",
      "name": "python",
      "nbconvert_exporter": "python",
      "pygments_lexer": "ipython3",
      "version": "3.10.11"
    }
  },
  "nbformat": 4,
  "nbformat_minor": 0
}
